Workbook

Sheet Historical Data
A1: Statement of Profit or Loss for the years ended 31 December
B2: 2018 | C2: =+B2+1 -> 2019 | D2: =+C2+1 -> 2020 | E2: =+D2+1 -> 2021 | F2: =+E2+1 -> 2022
A3: Sales Revenue | B3: 102007 | C3: 118086 | D3: 131345 | E3: 142341 | F3: 150772
A4: Cost of Sales | B4: -39023 | C4: -48004 | D4: -49123 | E4: -53254 | F4: -57310
A5: Gross Profit | B5: =SUM(B3:B4) -> 62984 | C5: =SUM(C3:C4) -> 70082 | D5: =SUM(D3:D4) -> 82222 | E5: =SUM(E3:E4) -> 89087 | F5: =SUM(F3:F4) -> 93462
A7: SG&A Expense | B7: -37390 | C7: -32783 | D7: -33959 | E7: -34022 | F7: -36657
A8: Depreciation Expense | B8: -19500 | C8: -18150 | D8: -17205 | E8: -16543.5 | F8: -16080.45
A9: Interest Expense | B9: -2500 | C9: -2500 | D9: -1500 | E9: -900 | F9: -900
A10: Income Before Income Taxes | B10: =SUM(B5:B9) -> 3594 | C10: =SUM(C5:C9) -> 16649 | D10: =SUM(D5:D9) -> 29558 | E10: =SUM(E5:E9) -> 37621.5 | F10: =SUM(F5:F9) -> 39824.55
A11: Income Taxes | B11: -1120.1708 | C11: -4858.2165 | D11: -8482.8061 | E11: -10908.021 | F11: -11597.665
A12: Profit after tax | B12: =SUM(B10:B11) -> 2473.8292 | C12: =SUM(C10:C11) -> 11790.783 | D12: =SUM(D10:D11) -> 21075.194 | E12: =SUM(E10:E11) -> 26713.479 | F12: =SUM(F10:F11) -> 28226.885
A14: Statement of Financial Position as at 31 December
A15: Assets
A16: Non-current Assets
A17: Property, Plant & Equipment | B17: 45500 | C17: 42350 | D17: 40145 | E17: 38601.5 | F17: 37521.05
A18: Current Assets
A19: Cash & Cash Equivalents | B19: 167971.18 | C19: 181209.91 | D19: 183715.26 | E19: 211069.34 | F19: 239549.52
A20: Accounts Receivable | B20: 5100.35 | C20: 5904.3 | D20: 6567.25 | E20: 7117.05 | F20: 7538.6
A21: Inventories | B21: 7804.6 | C21: 9600.8 | D21: 9824.6 | E21: 10530.8 | F21: 11342
A22: Total Current Assets | B22: =SUM(B19:B21) -> 180876.13 | C22: =SUM(C19:C21) -> 196715.01 | D22: =SUM(D19:D21) -> 200107.11 | E22: =SUM(E19:E21) -> 228717.19 | F22: =SUM(F19:F21) -> 258430.12
A23: Total Assets | B23: =+B22+B17 -> 226376.13 | C23: =+C22+C17 -> 239065.01 | D23: =+D22+D17 -> 240252.11 | E23: =+E22+E17 -> 267318.69 | F23: =+F22+F17 -> 295951.17
A25: Shareholders' Equity
A26: Share Capital | B26: 170000 | C26: 170000 | D26: 170000 | E26: 170000 | F26: 170000
A27: Retained Earnings | B27: 2473.8292 | C27: 14264.613 | D27: 35339.807 | E27: 62053.286 | F27: 90280.17
A28: Total Shareholders' Equity | B28: =SUM(B26:B27) -> 172473.83 | C28: =SUM(C26:C27) -> 184264.61 | D28: =SUM(D26:D27) -> 205339.81 | E28: =SUM(E26:E27) -> 232053.29 | F28: =SUM(F26:F27) -> 260280.17
A29: Non-current Liabilities
A30: Long-Term Debt | B30: 50000 | C30: 50000 | D30: 30000 | E30: 30000 | F30: 30000
A31: Total | B31: =SUM(B30) -> 50000 | C31: =SUM(C30) -> 50000 | D31: =SUM(D30) -> 30000 | E31: =SUM(E30) -> 30000 | F31: =SUM(F30) -> 30000
A32: Current Liabilities
A33: Accounts Payable | B33: 3902.3 | C33: 4800.4 | D33: 4912.3 | E33: 5265.4 | F33: 5671
A34: Total Current Liabilities | B34: =+B33 -> 3902.3 | C34: =+C33 -> 4800.4 | D34: =+D33 -> 4912.3 | E34: =+E33 -> 5265.4 | F34: =+F33 -> 5671
A35: Total Liabilities | B35: =B31+B34 -> 53902.3 | C35: =C31+C34 -> 54800.4 | D35: =D31+D34 -> 34912.3 | E35: =E31+E34 -> 35265.4 | F35: =F31+F34 -> 35671
A36: Total Liabilities and Shareholders' Equity | B36: =+B28+B35 -> 226376.13 | C36: =+C28+C35 -> 239065.01 | D36: =+D28+D35 -> 240252.11 | E36: =+E28+E35 -> 267318.69 | F36: =+F28+F35 -> 295951.17
A38: Statement of Cash Flows for the years ended 31 December
A39: Operating Activities
A40: Profit after tax | B40: 2473.8292 | C40: 11790.783 | D40: 21075.194 | E40: 26713.479 | F40: 28226.885
A41: Adjustments For:
A42: Depreciation Expense | B42: 19500 | C42: 18150 | D42: 17205 | E42: 16543.5 | F42: 16080.45
A43: Changes in Non-Cash Working Capital | B43: -9002.65 | C43: -1702.05 | D43: -774.85 | E43: -902.9 | F43: -827.15
A44: Cash Generated From Operating Activities | B44: =SUM(B40:B43) -> 12971.179 | C44: =SUM(C40:C43) -> 28238.733 | D44: =SUM(D40:D43) -> 37505.344 | E44: =SUM(E40:E43) -> 42354.079 | F44: =SUM(F40:F43) -> 43480.185
...

Sheet 3 Statement Model
C1: BUILDING A 3 STATEMENT FINANCIAL MODEL
A2: All figures are in USD | B2: 2018 | C2: =+B2+1 -> 2019 | D2: =+C2+1 -> 2020 | E2: =+D2+1 -> 2021 | F2: =+E2+1 -> 2022 | G2: =+F2+1 -> 2023 | H2: =+G2+1 -> 2024 | I2: =+H2+1 -> 2025 | J2: =+I2+1 -> 2026 | ... N2: =+M2+1 -> 2030
A3: Number of Days | B3: 365 | C3: 365 | D3: 365 | E3: 365 | F3: 365 | G3: 365 | H3: 365 | I3: 365 | J3: 365 | K3: 365 | L3: 365 | M3: 365 | N3: 365
A4: Balance Sheet Validation Check | B4: =IF(ABS(B45-B58)>1,"Error","OK") -> OK | C4: =IF(ABS(C45-C58)>1,"Error","OK") -> OK | D4: =IF(ABS(D45-D58)>1,"Error","OK") -> OK | E4: =IF(ABS(E45-E58)>1,"Error","OK") -> OK | F4: =IF(ABS(F45-F58)>1,"Error","OK") -> OK | G4: =IF(ABS(G45-G58)>1,"Error","OK") -> OK | H4: =IF(ABS(H45-H58)>1,"Error","OK") -> OK | I4: =IF(ABS(I45-I58)>1,"Error","OK") -> OK | ... N4: =IF(ABS(N45-N58)>1,"Error","OK") -> OK
A6: Assumptions and Drivers
A7: Statement of Profit/Loss:
A8: Sales Growth Rate | C8: =(C24/B24)-1 -> 0.15762644 | D8: =(D24/C24)-1 -> 0.11228257 | E8: =(E24/D24)-1 -> 0.083718451 | F8: =(F24/E24)-1 -> 0.059231002 | G8: 0.1 | H8: 0.1 | I8: 0.1 | J8: 0.1 | K8: 0.1 | L8: 0.1 | M8: 0.1 | N8: 0.1
A9: Gross Profit Margin | B9: =B26/B24 -> 0.61744782 | C9: =C26/C24 -> 0.59348272 | D9: =D26/D24 -> 0.62600023 | E9: =E26/E24 -> 0.62587027 | F9: =F26/F24 -> 0.61988963 | G9: 0.62 | H9: 0.62 | I9: 0.62 | J9: 0.62 | K9: 0.62 | L9: 0.62 | M9: 0.62 | N9: 0.62
A10: SG&A as a % of Sales | B10: =-B28/B24 -> 0.36654347 | C10: =-C28/C24 -> 0.2776197 | D10: =-D28/D24 -> 0.2585481 | E10: =-E28/E24 -> 0.23901757 | F10: =-F28/F24 -> 0.2431287 | G10: 0.2 | H10: 0.2 | I10: 0.2 | J10: 0.2 | K10: 0.2 | L10: 0.2 | M10: 0.2 | N10: 0.2
A11: Depreciation Expense as a % of Sales | B11: =-B29/B24 -> 0.19116335 | C11: =-C29/C24 -> 0.15370154 | D11: =-D29/D24 -> 0.1309909 | E11: =-E29/E24 -> 0.11622442 | F11: =-F29/F24 -> 0.10665409 | G11: 0.1 | H11: 0.1 | I11: 0.1 | J11: 0.1 | K11: 0.1 | L11: 0.1 | M11: 0.1 | N11: 0.1
A12: Interest Expense as a % of LTD | B12: =-B30/B52 -> 0.05 | C12: =-C30/C52 -> 0.05 | D12: =-D30/D52 -> 0.05 | E12: =-E30/E52 -> 0.03 | F12: =-F30/F52 -> 0.03 | G12: 0.03 | H12: 0.03 | I12: 0.03 | J12: 0.03 | K12: 0.03 | L12: 0.03 | M12: 0.03 | N12: 0.03
A13: Tax as a % of EBT | B13: =-B32/B31 -> 0.31167802 | C13: =-C32/C31 -> 0.2918023 | D13: =-D32/D31 -> 0.2869885 | E13: =-E32/E31 -> 0.28994115 | F13: =-F32/F31 -> 0.29121899 | G13: 0.3 | H13: 0.3 | I13: 0.3 | J13: 0.3 | K13: 0.3 | L13: 0.3 | M13: 0.3 | N13: 0.3
A15: Statement of Financial Position
A16: Capital Asset Turnover Ratio | B16: =B24/B39 -> 2.2419121 | C16: =C24/C39 -> 2.7883353 | D16: =D24/D39 -> 3.2717649 | E16: =E24/E39 -> 3.6874474 | F16: =F24/F39 -> 4.018331 | G16: 4 | H16: 4 | I16: 4 | J16: 4 | K16: 4 | L16: 4 | M16: 4 | N16: 4
A17: Receivable Days (Sales Basis) | B17: =B42/B24*B3 -> 18.25 | C17: =C42/C24*C3 -> 18.25 | D17: =D42/D24*D3 -> 18.25 | E17: =E42/E24*E3 -> 18.25 | F17: =F42/F24*F3 -> 18.25 | G17: 18 | H17: 18 | I17: 18 | J17: 18 | K17: 18 | L17: 18 | M17: 18 | N17: 18
A18: Inventory Days (COS Basis) | B18: =(B43/-B25)*B3 -> 73 | C18: =(C43/-C25)*C3 -> 73 | D18: =(D43/-D25)*D3 -> 73 | E18: =(E43/-E25)*E3 -> 72.177527 | F18: =(F43/-F25)*F3 -> 72.235735 | G18: 72 | H18: 72 | I18: 72 | J18: 72 | K18: 72 | L18: 72 | M18: 72 | N18: 72
A19: Payable Days (COS Basis) | B19: =(B55/-B25)*B3 -> 36.5 | C19: =(C55/-C25)*C3 -> 36.5 | D19: =(D55/-D25)*D3 -> 36.5 | E19: =(E55/-E25)*E3 -> 36.088763 | F19: =(F55/-F25)*F3 -> 36.117868 | G19: 36 | H19: 36 | I19: 36 | J19: 36 | K19: 36 | L19: 36 | M19: 36 | N19: 36
A20: Long Term Liabilities (LTL) | B20: =B52 -> 50000 | C20: =C52 -> 50000 | D20: =D52 -> 30000 | E20: =E52 -> 30000 | F20: =F52 -> 30000 | G20: 30000 | H20: 30000 | I20: 30000 | J20: 30000 | K20: 30000 | L20: 30000 | M20: 30000 | N20: 30000
A23: Statement of Profit/Loss
A24: Sales Revenue | B24: 102007 | C24: 118086 | D24: 131345 | E24: 142341 | F24: 150772 | G24: =F24*(1+G8) -> 165849.2 | H24: =G24*(1+H8) -> 182434.12 | I24: =H24*(1+I8) -> 200677.53 | J24: =I24*(1+J8) -> 220745.29 | K24: =J24*(1+K8) -> 242819.81 | L24: =K24*(1+L8) -> 267101.8 | M24: =L24*(1+M8) -> 293811.97 | N24: =M24*(1+N8) -> 323193.17
A25: Cost of Sales | B25: -39023 | C25: -48004 | D25: -49123 | E25: -53254 | F25: -57310 | G25: =G24*(1-G9) -> 63022.696 | H25: =H24*(1-H9) -> 69324.966 | I25: =I24*(1-I9) -> 76257.462 | J25: =J24*(1-J9) -> 83883.208 | K25: =K24*(1-K9) -> 92271.529 | L25: =L24*(1-L9) -> 101498.68 | M25: =M24*(1-M9) -> 111648.55 | N25: =N24*(1-N9) -> 122813.41
A26: Gross Profit | B26: =SUM(B24:B25) -> 62984 | C26: =SUM(C24:C25) -> 70082 | D26: =SUM(D24:D25) -> 82222 | E26: =SUM(E24:E25) -> 89087 | F26: =SUM(F24:F25) -> 93462 | G26: =G24-G25 -> 102826.5 | H26: =H24-H25 -> 113109.15 | I26: =I24-I25 -> 124420.07 | J26: =J24-J25 -> 136862.08 | K26: =K24-K25 -> 150548.28 | L26: =L24-L25 -> 165603.11 | M26: =M24-M25 -> 182163.42 | N26: =N24-N25 -> 200379.77
A28: SG&A Expense | B28: -37390 | C28: -32783 | D28: -33959 | E28: -34022 | F28: -36657 | G28: =-G10*G24 -> -33169.84 | H28: =-H10*H24 -> -36486.824 | I28: =-I10*I24 -> -40135.506 | J28: =-J10*J24 -> -44149.057 | K28: =-K10*K24 -> -48563.963 | L28: =-L10*L24 -> -53420.359 | M28: =-M10*M24 -> -58762.395 | N28: =-N10*N24 -> -64638.634
A29: Depreciation Expense | B29: -19500 | C29: -18150 | D29: -17205 | E29: -16543.5 | F29: -16080.45 | G29: =-G11*G24 -> -16584.92 | H29: =-H11*H24 -> -18243.412 | I29: =-I11*I24 -> -20067.753 | J29: =-J11*J24 -> -22074.529 | K29: =-K11*K24 -> -24281.981 | L29: =-L11*L24 -> -26710.18 | M29: =-M11*M24 -> -29381.197 | N29: =-N11*N24 -> -32319.317
A30: Interest Expense | B30: -2500 | C30: -2500 | D30: -1500 | E30: -900 | F30: -900 | G30: =-G12*G20 -> -900 | H30: =-H12*H20 -> -900 | I30: =-I12*I20 -> -900 | J30: =-J12*J20 -> -900 | K30: =-K12*K20 -> -900 | L30: =-L12*L20 -> -900 | M30: =-M12*M20 -> -900 | N30: =-N12*N20 -> -900
A31: Income Before Income Taxes | B31: =SUM(B26:B30) -> 3594 | C31: =SUM(C26:C30) -> 16649 | D31: =SUM(D26:D30) -> 29558 | E31: =SUM(E26:E30) -> 37621.5 | F31: =SUM(F26:F30) -> 39824.55 | G31: =SUM(G26:G30) -> 52171.744 | H31: =SUM(H26:H30) -> 57478.918 | I31: =SUM(I26:I30) -> 63316.81 | ... N31: =SUM(N26:N30) -> 102521.82
A32: Income Taxes | B32: -1120.1708 | C32: -4858.2165 | D32: -8482.8061 | E32: -10908.021 | F32: -11597.665 | G32: =-G13*G31 -> -15651.523 | H32: =-H13*H31 -> -17243.676 | I32: =-I13*I31 -> -18995.043 | J32: =-J13*J31 -> -20921.547 | K32: =-K13*K31 -> -23040.702 | L32: =-L13*L31 -> -25371.772 | M32: =-M13*M31 -> -27935.95 | N32: =-N13*N31 -> -30756.545
A33: Profit after tax | B33: =SUM(B31:B32) -> 2473.8292 | C33: =SUM(C31:C32) -> 11790.783 | D33: =SUM(D31:D32) -> 21075.194 | E33: =SUM(E31:E32) -> 26713.479 | F33: =SUM(F31:F32) -> 28226.885 | G33: =SUM(G31:G32) -> 36520.221 | H33: =SUM(H31:H32) -> 40235.243 | I33: =SUM(I31:I32) -> 44321.767 | ... N33: =SUM(N31:N32) -> 71765.271
A36: Statement of Financial Position
A37: Assets
A38: Non-current Assets
A39: Property, Plant & Equipment | B39: 45500 | C39: 42350 | D39: 40145 | E39: 38601.5 | F39: 37521.05 | G39: =G88 -> 41462.3 | H39: =H88 -> 45608.53 | I39: =I88 -> 50169.383 | J39: =J88 -> 55186.321 | K39: =K88 -> 60704.953 | L39: =L88 -> 66775.449 | M39: =M88 -> 73452.994 | N39: =N88 -> 80798.293
A40: Current Assets
A41: Cash & Cash Equivalents | B41: 167971.18 | C41: 181209.91 | D41: 183715.26 | E41: 211069.34 | F41: 239549.52 | G41: =G80 -> 270943.29 | H41: =H80 -> 305592.82 | I41: =I80 -> 343770.31 | J41: =J80 -> 385828.54 | K41: =K80 -> 432155.6 | L41: =L80 -> 483178.36 | M41: =M80 -> 539366.4 | N41: =N80 -> 601236.25
A42: Accounts Receivable | B42: 5100.35 | C42: 5904.3 | D42: 6567.25 | E42: 7117.05 | F42: 7538.6 | G42: =G17/G3*G24 -> 8178.8647 | H42: =H17/H3*H24 -> 8996.7511 | I42: =I17/I3*I24 -> 9896.4262 | J42: =J17/J3*J24 -> 10886.069 | K42: =K17/K3*K24 -> 11974.676 | L42: =L17/L3*L24 -> 13172.143 | M42: =M17/M3*M24 -> 14489.358 | N42: =N17/N3*N24 -> 15938.293
A43: Inventories | B43: 7804.6 | C43: 9600.8 | D43: 9824.6 | E43: 10530.8 | F43: 11342 | G43: =G18/G3*G25 -> 12431.874 | H43: =H18/H3*H25 -> 13675.062 | I43: =I18/I3*I25 -> 15042.568 | J43: =J18/J3*J25 -> 16546.825 | K43: =K18/K3*K25 -> 18201.507 | L43: =L18/L3*L25 -> 20021.658 | M43: =M18/M3*M25 -> 22023.824 | N43: =N18/N3*N25 -> 24226.206
A44: Total Current Assets | B44: =SUM(B41:B43) -> 180876.13 | C44: =SUM(C41:C43) -> 196715.01 | D44: =SUM(D41:D43) -> 200107.11 | E44: =SUM(E41:E43) -> 228717.19 | F44: =SUM(F41:F43) -> 258430.12 | G44: =SUM(G41:G43) -> 291554.03 | H44: =SUM(H41:H43) -> 328264.63 | I44: =SUM(I41:I43) -> 368709.3 | ... N44: =SUM(N41:N43) -> 641400.75
A45: Total Assets | B45: =+B44+B39 -> 226376.13 | C45: =+C44+C39 -> 239065.01 | D45: =+D44+D39 -> 240252.11 | E45: =+E44+E39 -> 267318.69 | F45: =+F44+F39 -> 295951.17 | G45: =+G44+G39 -> 333016.33 | H45: =+H44+H39 -> 373873.16 | I45: =+I44+I39 -> 418878.69 | ... N45: =+N44+N39 -> 722199.04
A47: Shareholders' Equity
A48: Share Capital | B48: 170000 | C48: 170000 | D48: 170000 | E48: 170000 | F48: 170000 | G48: 170000 | H48: 170000 | I48: 170000 | J48: 170000 | K48: 170000 | L48: 170000 | M48: 170000 | N48: 170000
...

Sheet Dashboard
B2: Revenue ($)- Forecast | E2: EBITDA - Forecast | I2: Free Cash Flow - Forecast | M2: EBITDA Margin - Forecast
B3: =H20 -> 165849.2 | C3: =O20 -> 323193.17 | E3: =H23 -> 69656.664 | G3: =O23 -> 135741.13 | I3: =H29 -> 31393.769 | K3: =O29 -> 61869.844 | M3: =H32 -> 0.42
B4: 2023 | C4: 2030 | F4: 2023 | G4: 2030 | J4: 2023 | K4: 2030 | M4: 2023
M17: Actuals through 2022, Forecast 2023–2030
B19: Metric | C19: ='3 Statement Model'!B2 -> 2018 | D19: ='3 Statement Model'!C2 -> 2019 | E19: ='3 Statement Model'!D2 -> 2020 | F19: ='3 Statement Model'!E2 -> 2021 | G19: ='3 Statement Model'!F2 -> 2022 | H19: ='3 Statement Model'!G2 -> 2023 | I19: ='3 Statement Model'!H2 -> 2024 | J19: ='3 Statement Model'!I2 -> 2025 | ... O19: ='3 Statement Model'!N2 -> 2030
B20: Sales Revenue | C20: ='3 Statement Model'!B24 -> 102007 | D20: ='3 Statement Model'!C24 -> 118086 | E20: ='3 Statement Model'!D24 -> 131345 | F20: ='3 Statement Model'!E24 -> 142341 | G20: ='3 Statement Model'!F24 -> 150772 | H20: ='3 Statement Model'!G24 -> 165849.2 | I20: ='3 Statement Model'!H24 -> 182434.12 | J20: ='3 Statement Model'!I24 -> 200677.53 | ... O20: ='3 Statement Model'!N24 -> 323193.17
B21: Actual Revenue | C21: =C20 -> 102007 | D21: =D20 -> 118086 | E21: =E20 -> 131345 | F21: =F20 -> 142341 | G21: =G20 -> 150772 | H21: =NA() -> #N/A | I21: =NA() -> #N/A | J21: =NA() -> #N/A | K21: =NA() -> #N/A | L21: =NA() -> #N/A | M21: =NA() -> #N/A | N21: =NA() -> #N/A | O21: =NA() -> #N/A
B22: Forecast Revenue | C22: =NA() -> #N/A | D22: =NA() -> #N/A | E22: =NA() -> #N/A | F22: =NA() -> #N/A | G22: =NA() -> #N/A | H22: =H20 -> 165849.2 | I22: =I20 -> 182434.12 | J22: =J20 -> 200677.53 | K22: =K20 -> 220745.29 | L22: =L20 -> 242819.81 | M22: =M20 -> 267101.8 | N22: =N20 -> 293811.97 | O22: =O20 -> 323193.17
B23: EBITDA | C23: ='3 Statement Model'!B26 + '3 Statement Model'!B28 -> 25594 | D23: ='3 Statement Model'!C26 + '3 Statement Model'!C28 -> 37299 | E23: ='3 Statement Model'!D26 + '3 Statement Model'!D28 -> 48263 | F23: ='3 Statement Model'!E26 + '3 Statement Model'!E28 -> 55065 | G23: ='3 Statement Model'!F26 + '3 Statement Model'!F28 -> 56805 | H23: ='3 Statement Model'!G26 + '3 Statement Model'!G28 -> 69656.664 | I23: ='3 Statement Model'!H26 + '3 Statement Model'!H28 -> 76622.33 | J23: ='3 Statement Model'!I26 + '3 Statement Model'!I28 -> 84284.563 | ... O23: ='3 Statement Model'!N26 + '3 Statement Model'!N28 -> 135741.13
B24: Net Income (PAT) | C24: ='3 Statement Model'!B33 -> 2473.8292 | D24: ='3 Statement Model'!C33 -> 11790.783 | E24: ='3 Statement Model'!D33 -> 21075.194 | F24: ='3 Statement Model'!E33 -> 26713.479 | G24: ='3 Statement Model'!F33 -> 28226.885 | H24: ='3 Statement Model'!G33 -> 36520.221 | I24: ='3 Statement Model'!H33 -> 40235.243 | J24: ='3 Statement Model'!I33 -> 44321.767 | ... O24: ='3 Statement Model'!N33 -> 71765.271
B25: Actual Revenue | C25: =C24 -> 2473.8292 | D25: =D24 -> 11790.783 | E25: =E24 -> 21075.194 | F25: =F24 -> 26713.479 | G25: =G24 -> 28226.885 | H25: =NA() -> #N/A | I25: =NA() -> #N/A | J25: =NA() -> #N/A | K25: =NA() -> #N/A | L25: =NA() -> #N/A | M25: =NA() -> #N/A | N25: =NA() -> #N/A | O25: =NA() -> #N/A
B26: Forecast Revenue | C26: =NA() -> #N/A | D26: =NA() -> #N/A | E26: =NA() -> #N/A | F26: =NA() -> #N/A | G26: =NA() -> #N/A | H26: =H24 -> 36520.221 | I26: =I24 -> 40235.243 | J26: =J24 -> 44321.767 | K26: =K24 -> 48816.944 | L26: =L24 -> 53761.638 | M26: =M24 -> 59200.802 | N26: =N24 -> 65183.882 | O26: =O24 -> 71765.271
B27: Cash From Ops (CFO) | C27: ='3 Statement Model'!B67 -> 12971.179 | D27: ='3 Statement Model'!C67 -> 28238.733 | E27: ='3 Statement Model'!D67 -> 37505.344 | F27: ='3 Statement Model'!E67 -> 42354.079 | G27: ='3 Statement Model'!F67 -> 43480.185 | H27: ='3 Statement Model'!G67 -> 51919.939 | I27: ='3 Statement Model'!H67 -> 57039.175 | J27: ='3 Statement Model'!I67 -> 62806.092 | ... O27: ='3 Statement Model'!N67 -> 101534.46
B28: CapEx (Additions to PPE) | C28: ='3 Statement Model'!B70 -> -15000 | D28: ='3 Statement Model'!C70 -> -15000 | E28: ='3 Statement Model'!D70 -> -15000 | F28: ='3 Statement Model'!E70 -> -15000 | G28: ='3 Statement Model'!F70 -> -15000 | H28: ='3 Statement Model'!G70 -> -20526.17 | I28: ='3 Statement Model'!H70 -> -22389.642 | J28: ='3 Statement Model'!I70 -> -24628.606 | ... O28: ='3 Statement Model'!N70 -> -39664.617
B29: Free Cash Flow (FCF) | C29: =C27 + C28 -> -2028.8208 | D29: =D27 + D28 -> 13238.733 | E29: =E27 + E28 -> 22505.344 | F29: =F27 + F28 -> 27354.079 | G29: =G27 + G28 -> 28480.185 | H29: =H27 + H28 -> 31393.769 | I29: =I27 + I28 -> 34649.533 | J29: =J27 + J28 -> 38177.486 | ... O29: =O27 + O28 -> 61869.844
B30: Actual FCF | C30: =C29 -> -2028.8208 | D30: =D29 -> 13238.733 | E30: =E29 -> 22505.344 | F30: =F29 -> 27354.079 | G30: =G29 -> 28480.185 | H30: =NA() -> #N/A | I30: =NA() -> #N/A | J30: =NA() -> #N/A | K30: =NA() -> #N/A | L30: =NA() -> #N/A | M30: =NA() -> #N/A | N30: =NA() -> #N/A | O30: =NA() -> #N/A
B31: Forecast FCF | C31: =NA() -> #N/A | D31: =NA() -> #N/A | E31: =NA() -> #N/A | F31: =NA() -> #N/A | G31: =NA() -> #N/A | H31: =H29 -> 31393.769 | I31: =I29 -> 34649.533 | J31: =J29 -> 38177.486 | K31: =K29 -> 42058.235 | L31: =L29 -> 46327.058 | M31: =M29 -> 51022.764 | N31: =N29 -> 56188.04 | O31: =O29 -> 61869.844
B32: EBITDA Margin (%) | C32: =IFERROR(C23/C20,0) -> 0.25090435 | D32: =IFERROR(D23/D20,0) -> 0.31586302 | E32: =IFERROR(E23/E20,0) -> 0.36745213 | F32: =IFERROR(F23/F20,0) -> 0.3868527 | G32: =IFERROR(G23/G20,0) -> 0.37676094 | H32: =IFERROR(H23/H20,0) -> 0.42 | I32: =IFERROR(I23/I20,0) -> 0.42 | J32: =IFERROR(J23/J20,0) -> 0.42 | ... O32: =IFERROR(O23/O20,0) -> 0.42
B33: FCF Margin (%) | C33: =IFERROR(C29/C20,0) -> -0.019889035 | D33: =IFERROR(D29/D20,0) -> 0.11211095 | E33: =IFERROR(E29/E20,0) -> 0.17134527 | F33: =IFERROR(F29/F20,0) -> 0.19217287 | G33: =IFERROR(G29/G20,0) -> 0.18889572 | H33: =IFERROR(H29/H20,0) -> 0.18929105 | I33: =IFERROR(I29/I20,0) -> 0.18992901 | J33: =IFERROR(J29/J20,0) -> 0.19024295 | ... O33: =IFERROR(O29/O20,0) -> 0.19143302
